Workbook

Sheet Cronograma de Trabajo
A2: CRONOGRAMA Y PLAN DE TRABAJO- FINANZAS
A5: SEMANAS / DÍAS | B5: PASOS | C5: ACTIVIDADES | D5: ENLACE DE ARCHIVOS | E5: TIEMPO (h) | F5: DÍAS | G5: ESTADO
B7: 1 | C7: Lee el objetivo y las actividades de esta semana | D7: SEMANA 1 | E7: 0.5 | F7: Día 1 | G7: COMPLETADA
A8: SEMANA 1 20 Noviembre al 26 Noviembre | B8: 2 | C8: Leer el glosario de conceptos básicos y ubica cada concepto en relación con tu negocio. | D8: Glosario de Conceptos Básicos | E8: 0.5 | F8: Días 1-3 | G8: COMPLETADA
B9: 3 | C9: Responder el cuestionario de salud financiera. | D9: Cuestionario de Salud Financiera | E9: 0.5 | F9: Días 3-5 | G9: COMPLETADA
B10: 4 | C10: Analizar los resultados obtenidos en el cuestionario. | E10: 0.5 | F10: Días 3-5 | G10: COMPLETADA
B11: 5 | C11: Realiza el ejercicio Acelerador de Resultados | G11: COMPLETADA
B14: 1 | C14: Lee el objetivo y las actividades de esta semana | D14: SEMANA 2 | E14: 0.5 | F14: Día 1 | G14: PENDIENTE
A15: SEMANA 2 27 Noviembre al 3 Dicembre | B15: 2 | C15: Llenar la pestaña 1 GASTOS. | D15: 1 GASTOS | E15: 1 | F15: Días 1-3 | G15: PENDIENTE
B16: 3 | C16: Llenar la pestaña 2 INGRESOS. | D16: 2 INGRESOS | E16: 0.5 | F16: Días 3-5 | G16: PENDIENTE
B17: 4 | C17: Llenar la pestaña 3 COMPENSACIÓN. | D17: 3 COMPENSACIÓN | E17: 0.5 | F17: Días 3-5 | G17: PENDIENTE
B18: 5 | C18: Realiza el ejercicio Acelerador de Resultados
B20: 1 | C20: Lee el objetivo y las actividades de esta semana | D20: SEMANA 3 | E20: 0.5 | F20: Día 1 | G20: PENDIENTE
A21: SEMANA 3 4 Diciembre al 10 Diciembre | B21: 2 | C21: Abrir 5 cuentas de Banco (Ingresos, Gastos Operativos, Ganancias, Compensación del dueño, Impuestos) | D21: BANCO DIGITAL REVOLUT | E21: 1 | F21: Días 1-3 | G21: PENDIENTE
B22: 3 | C22: Revisar la distribución de las partidas obtenidas. Sigue las instrucciones explicadas en la pestaña SEMANA 3. En función de los números obtenidos vas a tener que utilizar la pestaña 4 DISTRIBUCIÓN AL AZAR -NEGOCIO DE PRODUCTOS o la pestaña 4 DISTRIBUCIÓN AL AZAR -NEGOCIO DE SERVICIOS | E22: 1 | F22: Días 3-5 | G22: PENDIENTE
C23: NEGOCIOS DE PRODUCTOS | D23: 4 DISTRIBUCIÓN AL AZAR - NEGOCIOS DE PRODUCTOS | G23: PENDIENTE
C24: NEGOCIOS DE SERVICIOS | D24: 4 DISTRIBUCIÓN AL AZAR - NEGOCIOS DE SERVICIOS | G24: PENDIENTE
B25: 4 | C25: Valorar la situación financiera actual de tu negocio en función siguiendo los pasos explicados en la SEMANA 3 | E25: 0.5 | F25: Días 3-5 | G25: PENDIENTE
B26: 5 | C26: Realiza el ejercicio Acelerador de Resultados | E26: 0.5 | F26: Días 3-5 | G26: PENDIENTE
B29: 1 | C29: Lee el objetivo y las actividades de esta semana | D29: SEMANA 4 | E29: 0.5 | F29: Día 1 | G29: PENDIENTE
A30: SEMANA 4 11 Diciembre al 17 Diciembre | B30: 2 | C30: Establecer las metas del próximo trimestre. Archivo FINANZAS DE TU NEGOCIO / Pestaña “5 METAS DE DISTRIBUCIÓN...” que te corresponda, siguiendo las instrucciones explicadas en la pestaña SEMANA 4 | E30: 1 | F30: Días 1-3 | G30: PENDIENTE
C31: NEGOCIOS DE PRODUCTOS | D31: 5 METAS DE DISTRIBUCIÓN - NEGOCIOS DE PRODUCTOS | G31: PENDIENTE
C32: NEGOCIOS DE SERVICIOS | D32: 5 METAS DE DISTRIBUCIÓN - NEGOCIOS DE SERVICIOS | G32: PENDIENTE
B33: 3 | C33: Planifica la nueva distribución de las partidas financieras de tu negocio y analiza el impacto que tiene en tu negocio, siguiendo los pasos explicados en la pestaña de la SEMANA 4 | E33: 1 | F33: Días 3-5 | G33: PENDIENTE
B34: 4 | C34: Realiza el ejercicio Acelerador de Resultados | G34: PENDIENTE
B36: 1 | C36: Lee el objetivo y las actividades de esta semana | D36: SEMANA 5 | E36: 0.5 | F36: Día 1 | G36: PENDIENTE
A37: SEMANA 5 18 Diciembre al 24 Diciembre | B37: 2 | C37: Ordena tus cuentas de banco, siguiendo los pasos explicados en la pestaña de la SEMANA 5 | E37: 1 | F37: Días 1-3 | G37: PENDIENTE
B38: 3 | C38: Calcula el dinero a las diferentes cuentas, siguiendo los pasos explicados en la pestaña de la SEMANA 5 | E38: 1 | F38: Días 3-5 | G38: PENDIENTE
B39: 4 | C39: Realiza el ejercicio Acelerador de Resultados
A41: SEMANA 25 DICIEMBRE AL 1 DE ENERO | B41: DESCANSO
B43: 1 | C43: Lee el objetivo y las actividades de esta semana | D43: SEMANA 6 | E43: 0.5 | G43: PENDIENTE
A44: SEMANA 6 2 Enero al 7 Enero | B44: 2 | C44: EL DÍA 1 o 2 DE ENERO. Transfiere el dinero a las diferentes cuentas, siguiendo los pasos explicados en la pestaña de la SEMANA 5 | E44: 0.5 | G44: PENDIENTE
B45: 3 | C45: identifica los 5 gastos más importantes es tu negocio (los que representan el porcentaje más alto del total). 6 REDUCCIÓN DE GASTOS. | D45: 6 REDUCCIÓN DE GASTOS | E45: 0.5 | G45: PENDIENTE
B46: 4 | C46: Determina para esos 5 gastos si es factible que se puedan ELIMINAR, SUSTITUIR O RENEGOCIAR y escoge la opción en la tabla. Pestaña 6 REDUCCIÓN DE GASTOS. | E46: 0.5 | G46: PENDIENTE
B47: 5 | C47: Analiza y aplica las estrategias de reducción de gastos presentadas en el archivo ESTRATEGIAS DE REDUCCIÓN DE GASTOS que más se ajusten a tu situación financiera. | D47: ESTRATEGIAS Y PLAN DE REDUCCIÓN DE GASTOS | E47: 1 | G47: PENDIENTE
C48: Realiza el ejercicio Acelerador de Resultados | G48: PENDIENTE
B51: 1 | C51: Lee el objetivo y las actividades de esta semana | D51: SEMANA 7 | E51: 0.5 | G51: PENDIENTE
A52: SEMANA 7 8 Enero al 14 Enero | B52: 2 | C52: LLenar los datos para revisar el valor de cuánto es lo mínimo que tienes que facturar diariamente. Pestaña 7 CUÁNTO VENDER AL DÍA | D52: 7 CUÁNTO VENDER AL DÍA | E52: 0.5 | G52: PENDIENTE
B53: 3 | C53: LLenar los datos para revisar el valor de TICKET MEDIO. Pestaña 8 TICKET MEDIO | D53: 8 TICKET MEDIO | E53: 0.5 | G53: PENDIENTE
B54: 4 | C54: Analizar los resultados, siguiendo los pasos explicados en la pestaña de la SEMANA 7 | E54: 0.5 | G54: PENDIENTE
...

Sheet SEMANA 1

Sheet Glosario de Conceptos Básicos
B1: Glosario de Conceptos Básicos de Finanzas
B3: Concepto | C3: Explicación
B4: Facturación | C4: La cantidad total de dinero que ingresa a su negocio a través de ventas de productos o servicios.
B5: Gastos Fijos | C5: Los costos que se mantienen constantes mes a mes, como alquiler, salarios fijos, seguros, y arrendamientos.
B6: Gastos Variables | C6: Costos que cambian con la actividad del negocio, como suministros, comisiones, costos de publicidad, impuestos.
B7: Margen de Ganancia Bruto | C7: La diferencia entre sus ingresos y el costo directo de los productos o servicios que vendes. | D7: Supongamos que la compañía XYZ obtiene ingresos de 100 millones de euros al año, de los cuales 26 millones son beneficio bruto. El margen bruto sería del 26% (26 millones de euros / 100 millones de euros x 100) Aún tendrían que gastar parte de los 26 millones de euros en pagar a los accionistas o en liquidar otros gastos de la compañía, tales como honorarios e impuestos..
B8: Margen de Ganancia Neto | C8: Las ganancias después de restar todos los costos, incluyendo gastos fijos y variables, e impuestos.
B9: Flujo de Efectivo | C9: La cantidad de efectivo que entra y sale de su negocio. Un flujo de efectivo positivo es esencial para operar.
B10: Presupuesto | C10: Un plan financiero que detalla cómo planeas gastar y ganar dinero en tu negocio.
B11: Provisión para Impuestos | C11: El dinero que debes apartar para pagar impuestos sobre las ganancias de tu negocio.
B12: Inventario | C12: Los productos o bienes que tienes en existencia listos para ser vendidos.
B13: Balance General | C13: Un informe que muestra los activos, pasivos y el patrimonio neto de tu negocio en un momento específico.
B14: Estado de Resultados | C14: Un informe que detalla los ingresos y gastos durante un período para calcular la utilidad neta.
B15: Depreciación de Activos | C15: La disminución del valor de los activos, como equipo y mobiliario, con el tiempo.
B16: Rentabilidad | C16: La capacidad de tu negocio para generar beneficios en relación con los recursos invertidos.
B17: Proyecciones Financieras | C17: Estimaciones futuras de ingresos y gastos que te ayudan a planificar a largo plazo.
B18: Equidad | C18: El valor total de tu negocio después de pagar todas las deudas. También se llama patrimonio neto.
B19: Ratios Financieros | C19: Medidas como el margen de ganancia, la liquidez y la rotación de inventario que ayudan a evaluar la salud financiera.
... B22: ROI (Retorno de la Inversión) | C22: La ganancia o pérdida obtenida en relación con la inversión inicial en el negocio.

Sheet Cuestionario de Salud Financier
B2: Cuestionario para valorar de manera simple y rápida la salud financiera de tu negocio
B4: Responde cada pregunta con la respuesta que más se adapte a las acciones que tomas con tu negocio. Cuanto más sincera seas con tus respuestas, más fácil será detectar el problema y poder solucionarlo.
B6: Escribe el valor de la respuesta, siguiendo esta tabla:
B8: 1 PUNTO: “No” o “Casi Nunca”
B9: 2 PUNTOS: “Posiblemente” o “Algunas veces” o “En algunos casos”
B10: 3 PUNTOS: “Si” o “Con mucha frecuencia”
B12: Ahora puedes comenzar a responder:
B14: Preguntas | C14: Valor asignado (1, 2 o 3)
B15: ¿Te queda dinero en la cuenta bancaria de tu negocio a final de mes? | C15: 3
B16: ¿Te pagas un sueldo fijo cada mes? | C16: 3
B17: ¿Tienes control y mides todos tus ingresos mensuales? B | C17: 3
B18: ¿Conoces cuánto tienes que facturar cada mes para cubrir los costos fijos? | C18: 1
B19: ¿Tienes un presupuesto mensual de costos que sigues de cerca? | C19: 1
B20: ¿Tienes claro el inventario de productos que tienes en tu negocio y su valor? | C20: 2
B21: ¿Elaboras un plan financiero anual para tu negocio? | C21: 1
B22: ¿Tomas tiempo para detectar oportunidades de crecimiento? | C22: 1
B23: ¿Realizas una estimación anual de tus compromisos fiscales? | C23: 1
B24: ¿Trabajas con un gestor o asesor fiscal para optimizar tu situación tributaria? | C24: 3
B25: ¿Trabajas con un asesor financiero para optimizar tus inversiones? | C25: 1
B26: ¿Pagas todos tus costos y deudas con la facturación del negocio? | C26: 3
... B30: ¿Tienes separadas las cuentas bancarias del negocio y personales? | C30: 3
B31: ¿Tus empleados fijos siempre tienen la agenda llena y utilizan al máximo su tiempo de trabajo? | C31: 3 | D31: SI NO TIENES EMPLEADOS, RESPONDE ESTA PREGUNTA PENSANDO EN TU AGENDA DE TRABAJO Y EN LA OPTIMIZACIÓN DE TU TIEMPO DENTRO DEL NEGOCIO
B32: ¿Tienes más de un proveedor de productos o materia prima necesaria para tu negocio? | C32: 3
B33: ¿Con qué margen trabajas?
B34: PUNTAJE TOTAL | C34: =SUM(C15:C32) -> 39
B36: Revisa el total de puntos obtenido por tus respuestas. Un puntaje más alto indica una conducta financiera más saludable. Aquí hay una guía aproximada:
B38: 54-45 puntos: Buena salud financiera.
B39: 36-44 puntos: Mejorable, considera revisar y mejorar tus prácticas financieras.
B40: 18-35 puntos: Necesitas mejorar urgentemente tu salud financiera.
B43: Este cuestionario simplificado y la escala de respuestas te permitirán evaluar de manera rápida y general la salud financiera de tu negocio y tomar acciones para mejorar.

Sheet SEMANA 2

Sheet 1 GASTOS
A2: CLASIFICACIÓN DE GASTOS
A4: GASTOS FIJOS / GASTOS OPERATIVOS | B4: CANTIDAD MENSUAL | C4: CANTIDAD ANUAL | D4: % DE IMPORTANCIA de losgtos fijos | E4: % DE LOS INGRESOS
A5: Alquiler del local | B5: =C5/12 -> 0 | C5: ='1 GASTOS mensuales'!N5 -> 0 | D5: =C5/$C$25 -> 0 | E5: =C5/'2 INGRESOS'!C26 -> 0
A6: Salarios y sueldos del personal | B6: =C6/12 -> 491.66667 | C6: ='1 GASTOS mensuales'!N6 -> 5900 | D6: =C6/$C$25 -> 0.38352955 | E6: =C6/'2 INGRESOS'!C26 -> 0.13294576
A7: Servicios: Electricidad, agua, gas, y otros servicios públicos. | B7: =C7/12 -> 0 | C7: ='1 GASTOS mensuales'!N7 -> 0 | D7: =C7/$C$25 -> 0 | E7: =C7/'2 INGRESOS'!C26 -> 0
A8: Seguro del local | B8: =C8/12 -> 0 | C8: ='1 GASTOS mensuales'!N8 -> 0 | D8: =C8/$C$25 -> 0 | E8: =C8/'2 INGRESOS'!C26 -> 0
A9: Costos de licencias y permisos | B9: =C9/12 -> 41.25 | C9: ='1 GASTOS mensuales'!N9 -> 495 | D9: =C9/$C$25 -> 0.032177479 | E9: =C9/'2 INGRESOS'!C26 -> 0.011153924
A10: Materiales de limpieza | B10: =C10/12 -> 0 | C10: ='1 GASTOS mensuales'!N10 -> 0 | D10: =C10/$C$25 -> 0 | E10: =C10/'2 INGRESOS'!C26 -> 0
A11: Publicidad y marketing | B11: =C11/12 -> 212.5 | C11: ='1 GASTOS mensuales'!N11 -> 2550 | D11: =C11/$C$25 -> 0.16576277 | E11: =C11/'2 INGRESOS'!C26 -> 0.057459609
A12: Productos de oficina | B12: =C12/12 -> 11.666667 | C12: ='1 GASTOS mensuales'!N12 -> 140 | D12: =C12/$C$25 -> 0.0091007012 | E12: =C12/'2 INGRESOS'!C26 -> 0.0031546452
A13: Mantenimiento y reparaciones | B13: =C13/12 -> 41.916667 | C13: ='1 GASTOS mensuales'!N13 -> 503 | D13: =C13/$C$25 -> 0.032697519 | E13: =C13/'2 INGRESOS'!C26 -> 0.01133419
A14: Servicios de gestoría | B14: =C14/12 -> 83.225833 | C14: ='1 GASTOS mensuales'!N14 -> 998.71 | D14: =C14/$C$25 -> 0.064921152 | E14: =C14/'2 INGRESOS'!C26 -> 0.022504112
A15: Cuota de autónomos | B15: =C15/12 -> 96.28 | C15: ='1 GASTOS mensuales'!N15 -> 1155.36 | D15: =C15/$C$25 -> 0.075104187 | E15: =C15/'2 INGRESOS'!C26 -> 0.026033935
A16: Formación | B16: =C16/12 -> 73.293333 | C16: ='1 GASTOS mensuales'!N16 -> 879.52 | D16: =C16/$C$25 -> 0.057173205 | E16: =C16/'2 INGRESOS'!C26 -> 0.019818383
A17: Gastos bancarios | B17: =C17/12 -> -51.975833 | C17: ='1 GASTOS mensuales'!N17 -> -623.71 | D17: =C17/$C$25 -> -0.040544274 | E17: =C17/'2 INGRESOS'!C26 -> -0.01405417
A18: Web y comunicación | B18: =C18/12 -> 236.455 | C18: ='1 GASTOS mensuales'!N18 -> 2837.46 | D18: =C18/$C$25 -> 0.18444911 | E18: =C18/'2 INGRESOS'!C26 -> 0.063936997
A19: Telefonia | B19: =C19/12 -> 3.9833333 | C19: ='1 GASTOS mensuales'!N19 -> 47.8 | D19: =C19/$C$25 -> 0.0031072394 | E19: =C19/'2 INGRESOS'!C26 -> 0.001077086
A20: Otros | B20: =C20/12 -> 41.690833 | C20: ='1 GASTOS mensuales'!N20 -> 500.29 | D20: =C20/$C$25 -> 0.032521356 | E20: =C20/'2 INGRESOS'!C26 -> 0.011273125
A21: Otros | C21: =+B21*12 -> 0 | D21: =C21/$C$25 -> 0 | E21: =C21/'2 INGRESOS'!C26 -> 0
A22: Otros | C22: =+B22*12 -> 0 | D22: =C22/$C$25 -> 0 | E22: =C22/'2 INGRESOS'!C26 -> 0
A23: Otros | C23: =+B23*12 -> 0 | D23: =C23/$C$25 -> 0 | E23: =C23/'2 INGRESOS'!C26 -> 0
A24: Otros | C24: =+B24*12 -> 0 | D24: =C24/$C$25 -> 0 | E24: =C24/'2 INGRESOS'!C26 -> 0
A25: TOTAL | B25: =SUM(B5:B24) -> 1281.9525 | C25: =SUM(C5:C24) -> 15383.43 | D25: =C25/$C$25 -> 1 | E25: =C25/'2 INGRESOS'!C26 -> 0.3466376
A27: GASTOS VARIABLES | B27: CANTIDAD MENSUAL | C27: CANTIDAD ANUAL | D27: % DE LOS INGRESOS
A28: Flores | B28: =C28/12 -> 723.66667 | C28: ='1 GASTOS mensuales'!N25 -> 8684 | D28: =C28/'2 INGRESOS'!C26 -> 0.19567814
A29: Materiales (cristales etc) | B29: =C29/12 -> 223.66667 | C29: ='1 GASTOS mensuales'!N26 -> 2684 | D29: =C29/'2 INGRESOS'!C26 -> 0.060479055
A30: Packaging | B30: =C30/12 -> 78.083333 | C30: ='1 GASTOS mensuales'!N27 -> 937 | D30: =C30/'2 INGRESOS'!C26 -> 0.02111359
A31: Mensajería | B31: =C31/12 -> 55.505833 | C31: ='1 GASTOS mensuales'!N28 -> 666.07 | D31: =C31/'2 INGRESOS'!C26 -> 0.015008675 | E31: NO TE PREOCUPES POR ESTAS CELDAS, CUANDO LLENES LA PESTAÑA DE INGRESOS SE VAN A CALCULAR
A32: Contrataciones temporales- impuestos | B32: =C32/12 -> 124.16667 | C32: ='1 GASTOS mensuales'!N30 -> 1490 | D32: =C32/'2 INGRESOS'!C26 -> 0.033574438
A33: SUB TOTAL PRODUCTOS PARA LA VENTA Y PERSONAL SUBCONTRATADO | B33: =SUM(B28:B32) -> 1205.0892 | C33: =SUM(C28:C32) -> 14461.07 | D33: =SUM(D28:D32) -> 0.32585389
A34: Impuestos sobre la renta IRPF (Se paga una vez al año en Junio del año siguiente) | B34: =C34/11 -> 315 | C34: ='1 GASTOS mensuales'!N32 -> 3465 | D34: =C34/'2 INGRESOS'!C26 -> 0.078077469
A35: Pagos trimestrales | B35: =C35/11 -> 49.098182 | C35: ='1 GASTOS mensuales'!N33 -> 540.08 | D35: =C35/'2 INGRESOS'!C26 -> 0.01216972
A36: SUB TOTAL | B36: =SUM(B34:B35) -> 364.09818 | C36: =SUM(C34:C35) -> 4005.08 | D36: =C36/'2 INGRESOS'!C26 -> 0.090247189
A39: NOTAS:
A40: Si conoces la cantidad mensual del gasto (por ejemplo el alquiler), escríbela en la columna B, en la fila que corresponda, y ya la fórmula te calcula el anual en la columna C
A41: Si conoces la cantidad anual (por ejemplo, la del IRPF), escríbela directamente el la columna C, en la fila que corresponda
A42: SI LA CELDA D33 TE DA 30% O MAS: UTILIZA LA PESTAÑA 4 PARA NEGOCIOS DE PRODUCTOS
A43: SI LA CELDA D33 TE DA 29% O MENOS: UTILIZA LA PESTAÑA 4 PARA NEGOCIOS DE SERVICIOS
A44: Las celdas en gris NO LAS TOQUES

Sheet 1 GASTOS mensuales
A2: CLASIFICACIÓN DE GASTOS
A4: GASTOS FIJOS / GASTOS OPERATIVOS | B4: Ene | C4: Feb | D4: Mar | E4: Abr | F4: May | G4: Jun | H4: Jul | I4: Ago | J4: Sep | K4: Oct | L4: Nov | M4: Dic | N4: CANTIDAD ANUAL | O4: % DE IMPORTANCIA
A5: Alquiler del local | B5: 0 | C5: 0 | D5: 0 | E5: 0 | F5: 0 | G5: 0 | N5: =SUM(B5:M5) -> 0 | O5: =N5/$N$22 -> 0 | P5: Alquiler del local
A6: Salarios y sueldos del personal fijo (independ de las ventas) | B6: 800 | C6: 800 | D6: 800 | E6: 1000 | F6: 1000 | G6: 1500 | N6: =SUM(B6:M6) -> 5900 | O6: =N6/$N$22 -> 0.33940367 | P6: Salarios y sueldos del personal fijo (independ de las ventas)
A7: Servicios: Electricidad, agua, gas, y otros servicios públicos. | B7: 0 | C7: 0 | D7: 0 | E7: 0 | F7: 0 | G7: 0 | N7: =SUM(B7:M7) -> 0 | O7: =N7/$N$22 -> 0 | P7: Servicios: Electricidad, agua, gas, y otros servicios públicos.
A8: Seguro del local | B8: 0 | C8: 0 | D8: 0 | E8: 0 | F8: 0 | G8: 0 | N8: =SUM(B8:M8) -> 0 | O8: =N8/$N$22 -> 0 | P8: Seguro del local
A9: Costos de licencias y permisos | B9: 100 | C9: =35+21+23 -> 79 | D9: =20+35+23+18 -> 96 | E9: 74 | F9: 73 | G9: 73 | N9: =SUM(B9:M9) -> 495 | O9: =N9/$N$22 -> 0.028475393 | P9: Costos de licencias y permisos
A10: Materiales de limpieza | B10: 0 | C10: 0 | D10: 0 | E10: 0 | F10: 0 | G10: 0 | N10: 0 | O10: =N10/$N$22 -> 0 | P10: Materiales de limpieza
A11: Publicidad y marketing | B11: 21 | C11: =840+605+326+150 -> 1921 | D11: =72+536 -> 608 | E11: 0 | F11: 0 | G11: 0 | N11: =SUM(B11:M11) -> 2550 | O11: =N11/$N$22 -> 0.14669142 | P11: Publicidad y marketing
A12: Productos de oficina | B12: 0 | C12: 0 | D12: 10 | E12: 42 | F12: =32+46 -> 78 | G12: 10 | N12: =SUM(B12:M12) -> 140 | O12: =N12/$N$22 -> 0.0080536465 | P12: Productos de oficina
A13: Mantenimiento y reparaciones y muebles | B13: 0 | C13: 0 | D13: 0 | E13: 0 | F13: 0 | G13: =250+253 -> 503 | N13: =SUM(B13:M13) -> 503 | O13: =N13/$N$22 -> 0.028935601 | P13: Mantenimiento y reparaciones y muebles
A14: Servicios de gestoría | B14: 89.54 | C14: 71.39 | D14: 71.39 | E14: 71.39 | F14: 626 | G14: 69 | N14: =SUM(B14:M14) -> 998.71 | O14: =N14/$N$22 -> 0.057451838 | P14: Servicios de gestoría
A15: Cuota de autónomos | B15: 235.59 | C15: 235.59 | D15: 235.59 | E15: 235.59 | F15: 125 | G15: 88 | N15: =SUM(B15:M15) -> 1155.36 | O15: =N15/$N$22 -> 0.066463293 | P15: Cuota de autónomos
A16: Formación | B16: 0 | C16: 172.52 | D16: =165+83 -> 248 | E16: =159+20 -> 179 | F16: 160 | G16: 120 | N16: =SUM(C16:M16) -> 879.52 | O16: =N16/$N$22 -> 0.050595308 | P16: Formación
A17: Gastos bancarios | B17: =9.3+(-797) -> -787.7 | C17: 28 | D17: 42 | E17: 93.99 | N17: =SUM(B17:M17) -> -623.71 | O17: =N17/$N$22 -> -0.03587957 | P17: Gastos bancarios
A18: Web, comunicación, sistemas | B18: 530 | C18: 105 | D18: 0 | E18: =1206+18 -> 1224 | F18: =137.8+18 -> 155.8 | G18: =623.28+181.38+18 -> 822.66 | N18: =SUM(B18:M18) -> 2837.46 | O18: =N18/$N$22 -> 0.16322786 | P18: Web, comunicación, sistemas
A19: Telefonia | B19: 7.9 | C19: 7.9 | D19: 8 | E19: 8 | F19: 8 | G19: 8 | N19: =SUM(B19:M19) -> 47.8 | O19: =N19/$N$22 -> 0.002749745 | P19: Telefonia
A20: Otros | B20: 133.1 | C20: =47.19+72 -> 119.19 | D20: =42+33+20 -> 95 | E20: 20 | G20: 133 | N20: =SUM(B20:M20) -> 500.29 | O20: =N20/$N$22 -> 0.028779706 | P20: Otros
A21: Asesorías | B21: 400 | C21: 400 | D21: 400 | E21: 400 | F21: 400 | G21: 400 | N21: =SUM(C21:M21) -> 2000 | O21: =N21/$N$22 -> 0.11505209 | P21: Asesorías
A22: TOTAL | B22: =SUM(B5:B21) -> 1529.43 | C22: =SUM(C5:C21) -> 3939.59 | D22: =SUM(D5:D21) -> 2613.98 | E22: =SUM(E5:E21) -> 3347.97 | F22: =SUM(F5:F21) -> 2625.8 | G22: =SUM(G5:G21) -> 3726.66 | H22: =SUM(H5:H21) -> 0 | I22: =SUM(I5:I21) -> 0 | ... N22: =SUM(N5:N21) -> 17383.43 | O22: =N22/$N$22 -> 1 | P22: TOTAL
A24: GASTOS VARIABLES | B24: CANTIDAD MENSUAL | N24: CANTIDAD ANUAL | O24: % DE LOS INGRESOS | P24: GASTOS VARIABLES
A25: Flores | B25: 361 | C25: 1160 | D25: 913 | E25: 1560 | F25: 1470 | G25: 3220 | N25: =SUM(B25:M25) -> 8684 | O25: =N25/'2 INGRESOS'!C26 -> 0.19567814 | P25: Flores
A26: Materiales (cristales etc) | B26: 189 | C26: =360+14 -> 374 | D26: =177+235+26+231 -> 669 | E26: 677 | F26: 284 | G26: =13+478 -> 491 | N26: =SUM(B26:M26) -> 2684 | O26: =N26/'2 INGRESOS'!C26 -> 0.060479055 | P26: Materiales (cristales etc)
A27: Packaging | B27: 60 | C27: 83 | D27: 0 | E27: 293 | F27: 63 | G27: 438 | N27: =SUM(B27:M27) -> 937 | O27: =N27/'2 INGRESOS'!C26 -> 0.02111359 | P27: Packaging
A28: Mensajería | B28: 57.9 | C28: 44.17 | D28: 74 | E28: 101 | F28: 46 | G28: 343 | N28: =SUM(B28:M28) -> 666.07 | O28: =N28/'2 INGRESOS'!C26 -> 0.015008675 | P28: Mensajería
A29: Inmovilizados: maderas prensa, | E29: 200 | F29: 91 | G29: 91.4 | N29: =SUM(B29:M29) -> 382.4 | O29: =N29/'2 INGRESOS'!C26 -> 0.0086166881 | P29: Inmovilizados: maderas prensa,
A30: Contrataciones temporales- impuestos | B30: 160 | C30: =170+60 -> 230 | D30: ?? | E30: 1100 | F30: ?? | G30: ?? | N30: =SUM(B30:M30) -> 1490 | O30: =N30/'2 INGRESOS'!C26 -> 0.033574438 | P30: Contrataciones temporales- impuestos
A31: SUB TOTAL PRODUCTOS PARA LA VENTA Y PERSONAL SUBCONTRATADO | B31: =SUM(B25:B30) -> 827.9 | C31: =SUM(C25:C30) -> 1891.17 | D31: =SUM(D25:D30) -> 1656 | E31: =SUM(E25:E30) -> 3931 | F31: =SUM(F25:F30) -> 1954 | G31: =SUM(G25:G30) -> 4583.4 | H31: =SUM(H25:H30) -> 0 | I31: =SUM(I25:I30) -> 0 | ... O31: =SUM(O25:O30) -> 0.33447058 | P31: SUB TOTAL PRODUCTOS PARA LA VENTA Y PERSONAL SUBCONTRATADO
A32: Impuestos sobre la renta IRPF (Se paga una vez al año en Junio del año siguiente) | G32: 3465 | N32: =SUM(B32:M32) -> 3465 | O32: =N32/'2 INGRESOS'!C26 -> 0.078077469 | P32: Impuestos sobre la renta IRPF (Se paga una vez al año en Junio del año siguiente)
A33: Pagos trimestrales impuestos | B33: 240.08 | E33: =75+225 -> 300 | N33: =SUM(B33:M33) -> 540.08 | O33: =N33/'2 INGRESOS'!C26 -> 0.01216972 | P33: Pagos trimestrales impuestos
A34: SUB TOTAL | B34: =B31+B32+B33 -> 1067.98 | C34: =C31+C32+C33 -> 1891.17 | D34: =D31+D32+D33 -> 1656 | E34: =E31+E32+E33 -> 4231 | F34: =F31+F32+F33 -> 1954 | G34: =G31+G32+G33 -> 8048.4 | H34: =H31+H32+H33 -> 0 | I34: =I31+I32+I33 -> 0 | ... M34: =M31+M32+M33 -> 0 | N34: =SUM(N32:N33) -> 4005.08 | O34: =N34/'2 INGRESOS'!C26 -> 0.090247189 | P34: SUB TOTAL
N35: ç
A36: TOTAL GASTOS | B36: =B22+B34 -> 2597.41 | C36: =C22+C34 -> 5830.76 | D36: =D22+D34 -> 4269.98 | E36: =E22+E34 -> 7578.97 | F36: =F22+F34 -> 4579.8 | G36: =G22+G34 -> 11775.06 | H36: =H22+H34 -> 0 | I36: =I22+I34 -> 0 | J36: =J22+J34 -> 0
A38: NOTAS:
A39: Si conoces la cantidad mensual del gasto (por ejemplo el alquiler), escríbela en la columna B, en la fila que corresponda, y ya la fórmula te calcula el anual en la columna C
A40: Si conoces la cantidad anual (por ejemplo, la del IRPF), escríbela directamente el la columna C, en la fila que corresponda
A41: SI LA CELDA D23 TE DA 30% O MAS: UTILIZA LA PESTAÑA 4 PARA NEGOCIOS DE PRODUCTOS
A42: SI LA CELDA D23 TE DA 29% O MENOS: UTILIZA LA PESTAÑA 4 PARA NEGOCIOS DE SERVICIOS
A43: Las celdas en gris NO LAS TOQUES

Sheet 2 INGRESOS
A2: HOJA DE CLASIFICACIÓN DE INGRESOS
A4: INGRESOS / FACTURACIÓN / VENTAS | B4: CANTIDAD MENSUAL | C4: CANTIDAD ANUAL | D4: % DE IMPORTANCIA | E4: tiquet medio
A5: Novias | C5: ='2 INGRESOS mensuales'!N5 -> 25786 | D5: =C5/$C$26 -> 0.58104058
A6: Complementos | C6: ='2 INGRESOS mensuales'!N6 -> 891 | D6: =C6/$C$26 -> 0.020077063
A7: Productos web, cuadros , cupulas y varios | C7: ='2 INGRESOS mensuales'!N7 -> 1115 | D7: =C7/$C$26 -> 0.025124496
A8: Talleres | C8: ='2 INGRESOS mensuales'!N8 -> 853 | D8: =C8/$C$26 -> 0.019220803
A9: Sant Jordi | C9: ='2 INGRESOS mensuales'!N9 -> 5855 | D9: =C9/$C$26 -> 0.13193177
A10: Premsades | C10: ='2 INGRESOS mensuales'!N10 -> 4114 | D10: =C10/$C$26 -> 0.092701503
A11: Decoracions | C11: ='2 INGRESOS mensuales'!N11 -> 0 | D11: =C11/$C$26 -> 0
A12: B2B | C12: ='2 INGRESOS mensuales'!N12 -> 169 | D12: =C12/$C$26 -> 0.0038081074
A13: Formaciones | C13: ='2 INGRESOS mensuales'!N13 -> 5596 | D13: =C13/$C$26 -> 0.12609568
A14: Membresias | C14: =+B14*12 -> 0 | D14: =C14/$C$26 -> 0
C15: =+B15*12 -> 0 | D15: =C15/$C$26 -> 0
C16: =+B16*12 -> 0 | D16: =C16/$C$26 -> 0
C17: =+B17*12 -> 0 | D17: =C17/$C$26 -> 0
C18: =+B18*12 -> 0 | D18: =C18/$C$26 -> 0
C19: =+B19*12 -> 0 | D19: =C19/$C$26 -> 0
C20: =+B20*12 -> 0 | D20: =C20/$C$26 -> 0
C21: =+B21*12 -> 0 | D21: =C21/$C$26 -> 0
C22: =+B22*12 -> 0 | D22: =C22/$C$26 -> 0
C23: =+B23*12 -> 0 | D23: =C23/$C$26 -> 0
C24: =+B24*12 -> 0 | D24: =C24/$C$26 -> 0
C25: =+B25*12 -> 0 | D25: =C25/$C$26 -> 0
A26: TOTAL | B26: =SUM(B5:B25) -> 0 | C26: =SUM(C5:C25) -> 44379 | D26: =C26/$C$26 -> 1

Sheet 2 INGRESOS mensuales
A2: HOJA DE CLASIFICACIÓN DE INGRESOS
A4: INGRESOS / FACTURACIÓN / VENTAS | B4: Ene | C4: Feb | D4: Mar | E4: Abr | F4: May | G4: Jun | H4: Jul | I4: Ago | J4: Sep | K4: Oct | L4: Nov | M4: Dic | N4: CANTIDAD ANUAL | O4: % DE IMPORTANCIA
A5: Novias | B5: 2426 | C5: 2674 | D5: 2923 | E5: 4329 | F5: =250+5960 -> 6210 | G5: 7224 | N5: =SUM(B5:M5) -> 25786 | O5: =N5/$N$26 -> 0.58104058 | P5: Novias
A6: Complementos | B6: 69 | C6: 56 | D6: 267 | E6: =67+95 -> 162 | F6: 40 | G6: =161+136 -> 297 | N6: =SUM(B6:M6) -> 891 | O6: =N6/$N$26 -> 0.020077063 | P6: Complementos
A7: Productos web, cuadros , cupulas y varios | B7: 230 | C7: 42 | D7: 266 | E7: 514 | F7: 63 | G7: 0 | N7: =SUM(B7:M7) -> 1115 | O7: =N7/$N$26 -> 0.025124496 | P7: Productos web, cuadros , cupulas y varios
A8: Talleres | B8: 288 | C8: 0 | D8: =171+114 -> 285 | E8: 0 | F8: 280 | G8: 0 | N8: =SUM(B8:M8) -> 853 | O8: =N8/$N$26 -> 0.019220803 | P8: Talleres
A9: Sant Jordi | B9: 0 | C9: 0 | D9: 0 | E9: 5855 | F9: 0 | G9: 0 | H9: 0 | I9: 0 | J9: 0 | K9: 0 | L9: 0 | M9: 0 | N9: =SUM(B9:M9) -> 5855 | O9: =N9/$N$26 -> 0.13193177 | P9: Sant Jordi
A10: Premsades | B10: 743 | C10: 571 | D10: 621 | E10: 600 | F10: =214+706 -> 920 | G10: 659 | N10: =SUM(B10:M10) -> 4114 | O10: =N10/$N$26 -> 0.092701503 | P10: Premsades
A11: Decoracions | B11: 0 | C11: 0 | D11: 0 | E11: 0 | F11: 0 | G11: 0 | N11: =SUM(B11:M11) -> 0 | O11: =N11/$N$26 -> 0 | P11: Decoracions
A12: B2B | B12: 20 | C12: 149 | D12: 0 | E12: 0 | F12: 0 | G12: 0 | N12: =SUM(B12:M12) -> 169 | O12: =N12/$N$26 -> 0.0038081074 | P12: B2B
A13: Formaciones | B13: 0 | C13: 0 | D13: 0 | E13: 0 | F13: 0 | G13: 5596 | N13: =SUM(B13:M13) -> 5596 | O13: =N13/$N$26 -> 0.12609568 | P13: Florece
A14: Membresias | N14: =SUM(B14:M14) -> 0
N15: =SUM(B15:M15) -> 0
N16: =SUM(B16:M16) -> 0
N17: =SUM(B17:M17) -> 0
N18: =SUM(B18:M18) -> 0
N19: =SUM(B19:M19) -> 0
N20: =SUM(B20:M20) -> 0
N21: =SUM(B21:M21) -> 0
N22: =SUM(B22:M22) -> 0
N23: =SUM(B23:M23) -> 0
N24: =SUM(B24:M24) -> 0
N25: =SUM(B25:M25) -> 0
A26: TOTAL | B26: =SUM(B5:B25) -> 3776 | C26: =SUM(C5:C25) -> 3492 | D26: =SUM(D5:D25) -> 4362 | E26: =SUM(E5:E25) -> 11460 | F26: =SUM(F5:F25) -> 7513 | G26: =SUM(G5:G25) -> 13776 | H26: =SUM(H5:H25) -> 0 | I26: =SUM(I5:I25) -> 0 | ... N26: =SUM(N5:N25) -> 44379
A28: Reservas ramo (€) | B28: 1800 | C28: 2100 | D28: 1700 | E28: 1400 | F28: =100*F29 -> 2000 | G28: =100*G29 -> 300 | N28: =SUM(B28:M28) -> 9300
A29: Reservas cantidad mensual | B29: 18 | C29: 21 | D29: 17 | E29: 14 | F29: 20 | G29: 3 | N29: =SUM(B29:M29) -> 93
A30: Reservas cuadro premsadas (€) | B30: 300 | C30: 300 | D30: 200 | E30: 600 | F30: =100*F31 -> 600 | G30: =100*G31 -> 500 | H30: =100*H31 -> 0 | I30: =100*I31 -> 0 | N30: =SUM(B30:M30) -> 2500
A31: Cantidad cuadro premsado | B31: 3 | C31: 3 | D31: 2 | E31: 6 | F31: 6 | G31: 5 | N31: =SUM(B31:M31) -> 25
A34: FACTURACION POR CANAL DE VENTA | B34: Ene | C34: Feb | D34: Mar | E34: Abr | F34: May | G34: Jun | H34: Jul | I34: Ago | J34: Sep | K34: Oct | L34: Nov | M34: Dic | N34: CANTIDAD ANUAL | O34: % DE IMPORTANCIA
A35: Referencias | B35: 0 | C35: 300 | D35: 310 | E35: 292 | F35: 0 | G35: 0 | N35: =SUM(B35:M35) -> 902 | O35: =N35/$N$26 -> 0.020324928 | Q35: Referencias
A36: Google | B36: 600 | C36: 471 | D36: 635 | E36: 500 | F36: =40+100 -> 140 | G36: 155 | N36: =SUM(B36:M36) -> 2501 | O36: =N36/$N$26 -> 0.056355483 | Q36: Google
A37: Instagram | B37: =93+512 -> 605 | C37: 800 | D37: =197+40+400+127+171 -> 935 | E37: =412+384 -> 796 | F37: =521+1029+100+300+900+250+105+106 -> 3311 | G37: =920+792+200+100+100+109 -> 2221 | N37: =SUM(B37:M37) -> 8668 | O37: =N37/$N$26 -> 0.19531761 | Q37: Instagram
A38: Bodas.net | B38: 298 | C38: 634 | D38: 0 | E38: 0 | F38: 100 | G38: 0 | N38: =SUM(B38:M38) -> 1032 | O38: =N38/$N$26 -> 0.023254242 | Q38: Bodas.net
A39: Wedding planners, proveïdors | B39: 0 | C39: 100 | D39: 100 | E39: 516 | F39: =214+200 -> 414 | G39: 50 | N39: =SUM(B39:M39) -> 1180 | O39: =N39/$N$26 -> 0.026589153 | Q39: Wedding planners, proveïdors
A40: Madrigal | B40: 400 | C40: 300 | D40: 100 | E40: 518 | F40: 0 | G40: 0 | N40: =SUM(B40:M40) -> 1318 | O40: =N40/$N$26 -> 0.029698731 | Q40: Madrigal
A41: Conocidos | B41: 0 | C41: 42 | D41: 0 | E41: 0 | F41: 0 | G41: 0 | N41: =SUM(B41:M41) -> 42 | O41: =N41/$N$26 -> 0.00094639356 | Q41: Conocidos
A42: Escaparate | B42: 0 | C42: 0 | D42: 0 | E42: 0 | F42: 0 | G42: 0 | N42: =SUM(B42:M42) -> 0 | O42: =N42/$N$26 -> 0 | Q42: Escaparate
A43: Cliente reiterado | B43: 92 | C43: 149 | D43: 0 | E43: =35+210 -> 245 | F43: 280 | G43: 100 | N43: =SUM(B43:M43) -> 866 | O43: =N43/$N$26 -> 0.019513734 | Q43: Cliente reiterado
A44: Tik-Tok | B44: 1197 | C44: 693 | D44: 2165 | E44: =695+1943+100 -> 2738 | F44: =1600+900 -> 2500 | G44: =5500+3946+96+200+271+150+150 -> 10313 | N44: =SUM(B44:M44) -> 19606 | O44: =N44/$N$26 -> 0.44178553 | Q44: Tik-Tok
A45: Fires | B45: 0 | C45: 0 | D45: 0 | E45: 0 | F45: 0 | G45: 0 | N45: =SUM(B45:M45) -> 0 | O45: =N45/$N$26 -> 0 | Q45: Fires
...

Sheet 3 COMPENSACIÓN
A2: HOJA DE CLASIFICACIÓN DE COMPENSACIÓN / SALARIO
A4: INGRESOS / FACTURACIÓN / VENTAS | B4: CANTIDAD MENSUAL | C4: CANTIDAD ANUAL
A5: Dinero que tengo asignado para cobrar a final de mes | B5: 1000 | C5: =+B5*12 -> 12000
A6: Efectivo que suelo retirar de la caja para pagar cosas personales | B6: 0 | C6: =+B6*12 -> 0
A7: Gastos personales que pago con la cuenta del negocio | B7: 0
C8: =+B8*12 -> 0
C9: =+B9*12 -> 0
C10: =+B10*12 -> 0
C11: =+B11*12 -> 0
C12: =+B12*12 -> 0
C13: =+B13*12 -> 0
C14: =+B14*12 -> 0
C15: =+B15*12 -> 0
C16: =+B16*12 -> 0
C17: =+B17*12 -> 0
C18: =+B18*12 -> 0
C19: =+B19*12 -> 0
A20: TOTAL | B20: =SUM(B5:B19) -> 1000 | C20: =SUM(C5:C19) -> 12000
A23: NOTA: Si no tienes un sueldo asignado y no tienes ni idea de cuanto dinero has tomado de la caja o de la cuenta bancaria, entonces no llenes este cuadro
A28: EJEMPLOS
A29: HOJA DE CLASIFICACIÓN DE INGRESOS PELUQUERÍA Y ESTÉTICA
A31: INGRESOS / FACTURACIÓN / VENTAS | B31: CANTIDAD MENSUAL | C31: CANTIDAD ANUAL
A32: Venta de productos cabello | C32: =+B32*12 -> 0
A33: Venta de prodcutos faciales | C33: =+B33*12 -> 0
A34: Venta de productos corporales | C34: =+B34*12 -> 0
A35: Servicios de peluquería | C35: =+B35*12 -> 0
A36: Servicios Faciales | C36: =+B36*12 -> 0
A37: Servicios Corporales | C37: =+B37*12 -> 0
A38: Sub-arriendo de Cabina | C38: =+B38*12 -> 0
A39: Servicios exras a domicilio | C39: =+B39*12 -> 0
A40: Colaboraciones con otros profesionales | C40: =+B40*12 -> 0
C41: =+B41*12 -> 0
C42: =+B42*12 -> 0
C43: =+B43*12 -> 0
C44: =+B44*12 -> 0
C45: =+B45*12 -> 0
C46: =+B46*12 -> 0
A47: TOTAL | B47: =SUM(B32:B46) -> 0 | C47: =SUM(C32:C46) -> 0
A50: HOJA DE CLASIFICACIÓN DE INGRESOS ESTUDIO DE FOTOGRAFÍA
A52: INGRESOS / FACTURACIÓN / VENTAS | B52: CANTIDAD MENSUAL | C52: CANTIDAD ANUAL
...

Sheet SEMANA 3

Sheet 4 DISTRIBUCIÓN AL AZAR -NEGOCIO
B2: DISTRIBUCIÓN DE TUS PARTIDAS - NEGOCIOS DE PRODUCTOS
C4: Lo que estoy haciendo este año en € | D4: Porcentaje de distribución al azar | E4: DISPOSICIÓN IDEAL
B5: Ingreso Total | C5: ='2 INGRESOS'!C26 -> 44379 | F5: =C5 -> 44379 | G5: CUENTA 1 INGRESOS
B6: Productos/Sub.-relacionado con ventas | C6: ='1 GASTOS'!C33 -> 14461.07 | D6: =(C6*1)/C5 -> 0.32585389 | E6: 0.3 | F6: =(F5*E6)/1 -> 13313.7 | G6: CUENTA 5 GASTOS OPERATIVOS O CREAR LA 6
B7: Ingreso Bruto | C7: =C5-C6 -> 29917.93 | F7: =F5-F6 -> 31065.3
B8: Ganancia | C8: 0 | D8: =(C8*1)/C7 -> 0 | E8: 0.08 | F8: =(F7*E8)/1 -> 2485.224 | G8: CUENTA 3 GANANCIA
B9: Compensación Dueño | C9: ='3 COMPENSACIÓN'!C20 -> 12000 | D9: =(C9*1)/C7 -> 0.40109727 | E9: 0.35 | F9: =(F7*E9)/1 -> 10872.855 | G9: CUENTA 2 COMPENSACIÓN DUEÑO
B10: Impuestos | C10: ='1 GASTOS'!C36 -> 4005.08 | D10: =(C10*1)/C7 -> 0.13386889 | E10: 0.17 | F10: =(F7*E10)/1 -> 5281.101 | G10: CUENTA 4 IMPUESTOS
B11: Gastos Operación fijos e indep.de ventas | C11: ='1 GASTOS'!C25 -> 15383.43 | D11: =(C11*1)/C7 -> 0.51418765 | E11: 0.4 | F11: =(F7*E11)/1 -> 12426.12 | G11: CUENTA 5 GASTOS OPERATIVOS
C13: =SUM(C8:C11) -> 31388.51 | D13: =SUM(D8:D11) -> 1.0491538 | E13: =SUM(E8:E11) -> 1 | F13: =SUM(F8:F11) -> 31065.3
B15: CASILLAS VERIFICACIÓN | C15: C7 | D15: 1 | E15: 1 | F15: F7
B18: NIVEL BÁSICO | F18: FILA 13 Y 15
F19: SOLO DEBEMOS COMPOBAR QUE COINCIDAN (C13=C7 Y F13=F7)
B20: INFORMACIÓN DE CADA CASILLA
B22: B5 | C22: INGRESO TOTAL | D22: Viene de la pestaña 2 INGRESOS, C20
B23: B6 | C23: PRODUCTOS QUE COMPRAS PARA VENDER + PERSONAL SUBCONTRATADO NECESARIO PARA PRESTAR UN SERVICIO AL CLIENTE) | D23: Viene de la pestaña 1 GASTOS, C23 | G23: =30000+G22 -> 30000
B24: B7 | C24: INGRESO BRUTO | D24: Es la diferencia de las dos primeras.
B25: B8 | C25: GANANCIA - BENEFICIO | D25: Ganancia o beneficio de la empresa. No es tu sueldo. Esto es el dineo que queda en el banco a final de año despues de pagar TODOS los gastos, incluyendo impuestos. | F25: CASILLA GANACIAS
B26: B9 | C26: COMPENSACIÓN DEL DUEÑO | D26: Viene de la pestaña 3 COMPENSACIÓN, C20 | F26: La distrubución es un premio para las personas que han invertido dinero en el negocio
B27: B10 | C27: IMPUESTOS | D27: Viene de la pestaña 1 GASTOS, C26 | F27: No confundas ganancia con sueldo del dueño.
B28: B11 | C28: GASTOS DE OPERACIÓN | D28: Viene de la pestaña 1 GASTOS, C18 | F28: El sueldo es por trabajar, la ganancia es por invertir. Como las acciones
F29: Si hay préstamos 1% a socios y 99% a préstamos comenzando por el de menor importe
F30: Colchón de 3 meses sobre gastos.
C31: COLUMNA D
C32: Te va a decir como distibuyes actualmente el dinero que entra en la empresa en %. (No tocar)
B34: BÁSICO - LEEMOS NÚMEROS - COLUMNA E
B35: E8 | C35: GANANCIA - BENEFICIO | D35: Este es el porcentaje del ingreso bruto que deberías destinar a ganancia.
B36: E9 | C36: COMPENSACIÓN DEL DUEÑO | D36: Este es el porcentaje del ingreso bruto que deberías destinar a tu sueldo.
B37: E10 | C37: IMPUESTOS | D37: Este es el porcentaje del ingreso bruto que deberías destinar a Impuestos. Aunque la mejor forma de saberlo es ver años anteriores.
B38: E11 | C38: GASTOS DE OPERACIÓN | D38: Este es el porcentaje del ingreso bruto que deberías destinar a gastos operativos.
C41: COLUMNA F
C42: Te va a decir como deberías distibuir ese porcentaje en dinero. (No tocar)

Sheet 4 DISTRIBUCIÓN AL AZAR-NEGOCIO 
B2: DISTRIBUCIÓN DE TUS PARTIDAS - NEGOCIOS DE SERVICIOS
C4: Lo que hice el año pasado en € | D4: Porcentaje de distribución al azar | E4: DISPOSICIÓN IDEAL
B5: Ingreso Total | C5: ='2 INGRESOS'!C26 -> 44379 | F5: =C5 -> 44379 | G5: CUENTA 1 INGRESOS
B6: Productos/Sub. | C6: 0 | D6: =(C6*1)/C5 -> 0 | E6: 0 | F6: =(F5*E6)/1 -> 0 | G6: CUENTA 5 GASTOS OPERATIVOS O CREAR LA 6
B7: Ingreso bruto | C7: =C5-C6 -> 44379 | F7: =F5-F6 -> 44379
B8: Ganancia | C8: 0 | D8: =(C8*1)/C7 -> 0 | E8: 0.08 | F8: =(F7*E8)/1 -> 3550.32 | G8: CUENTA 3 GANANCIA
B9: Compensación Dueño | C9: ='3 COMPENSACIÓN'!C20 -> 12000 | D9: =(C9*1)/C7 -> 0.27039816 | E9: 0.35 | F9: =(F7*E9)/1 -> 15532.65 | G9: CUENTA 2 COMPENSACIÓN DUEÑO
B10: Impuestos | C10: ='1 GASTOS'!C36 -> 4005.08 | D10: =(C10*1)/C7 -> 0.090247189 | E10: 0.17 | F10: =(F7*E10)/1 -> 7544.43 | G10: CUENTA 4 IMPUESTOS
B11: Gastos Operación | C11: ='1 GASTOS'!C25+'1 GASTOS'!C33 -> 29844.5 | D11: =(C11*1)/C7 -> 0.67249149 | E11: 0.4 | F11: =(F7*E11)/1 -> 17751.6 | G11: CUENTA 5 GASTOS OPERATIVOS
C13: =SUM(C8:C11) -> 45849.58 | D13: =SUM(D8:D11) -> 1.0331368 | E13: =SUM(E8:E11) -> 1 | F13: =SUM(F8:F11) -> 44379
B15: CASILLAS VERIFICACIÓN | C15: C7 | D15: 1 | E15: 1 | F15: F7
B18: NIVEL BÁSICO | F18: FILA 13 Y 15
F19: SOLO DEBEMOS COMPOBAR QUE COINCIDAN (C13=C7 Y F13=F7)
B20: INFORMACIÓN DE CADA CASILLA
B22: B5 | C22: INGRESO TOTAL | D22: Viene de la pestaña 2 INGRESOS, C20
B23: B6 | C23: PRODUCTOS QUE COMPRAS PARA VENDER + PERSONAL SUBCONTRATADO NECESARIO PARA PRESTAR UN SERVICIO AL CLIENTE) | D23: Viene de la pestaña 1 GASTOS, C23
B24: B7 | C24: INGRESO BRUTO | D24: Es la diferencia de las dos primeras.
B25: B8 | C25: GANANCIA - BENEFICIO | D25: Ganancia o beneficio de la empresa. No es tu sueldo. Esto es el dineo que queda en el banco a final de año despues de pagar TODOS los gastos, incluyendo impuestos. | F25: CASILLA GANACIAS
B26: B9 | C26: COMPENSACIÓN DEL DUEÑO | D26: Viene de la pestaña 3 COMPENSACIÓN, C20 | F26: La distrubución es un premio para las personas que han invertido dinero en el negocio
B27: B10 | C27: IMPUESTOS | D27: Viene de la pestaña 1 GASTOS, C26 | F27: No confundas ganancia con sueldo del dueño.
B28: B11 | C28: GASTOS DE OPERACIÓN | D28: Viene de la pestaña 1 GASTOS, C18 | F28: El sueldo es por trabajar, la ganancia es por invertir. Como las acciones
F29: Si hay préstamos 1% a socios y 99% a préstamos comenzando por el de menor importe
F30: Colchón de 3 meses sobre gastos.
C31: COLUMNA D
C32: Te va a decir como distibuyes actualmente el dinero que entra en la empresa en %. (No tocar)
B34: BÁSICO - LEEMOS NÚMEROS - COLUMNA E
B35: E8 | C35: GANANCIA - BENEFICIO | D35: Este es el porcentaje del ingreso bruto que deberías destinar a ganancia.
B36: E9 | C36: COMPENSACIÓN DEL DUEÑO | D36: Este es el porcentaje del ingreso bruto que deberías destinar a tu sueldo.
B37: E10 | C37: IMPUESTOS | D37: Este es el porcentaje del ingreso bruto que deberías destinar a Impuestos. Aunque la mejor forma de saberlo es ver años anteriores.
B38: E11 | C38: GASTOS DE OPERACIÓN | D38: Este es el porcentaje del ingreso bruto que deberías destinar a gastos operativos.
C41: COLUMNA F
C42: Te va a decir como deberías distibuir ese porcentaje en dinero. (No tocar)

Sheet SEMANA 4

Sheet 5 META DE DISTRIBUCIÓN - NEGOCI
B2: METAS DE DISTRIBUCIÓN DE TUS PARTIDAS - NEGOCIOS DE PRODUCTOS
C4: Lo que estoy haciendo este año en € | D4: Porcentaje de distribución al azar | E4: DISPOSICIÓN IDEAL | G4: % PRÓXIMO TRIMESTRE €
B5: Ingreso Total | C5: ='2 INGRESOS'!C26 -> 44379 | F5: =C5 -> 44379 | H5: 3180
B6: Productos/Sub. | C6: ='1 GASTOS'!C33 -> 14461.07 | D6: =(C6*1)/C5 -> 0.32585389 | E6: 0.3 | F6: =(F5*E6)/1 -> 13313.7 | G6: 0.4 | H6: =(H5*G6)/1 -> 1272
B7: Ingreso Bruto | C7: =C5-C6 -> 29917.93 | F7: =F5-F6 -> 31065.3 | G7: 0.4 | H7: =H5-H6 -> 1908
B8: Ganancia / Beneficio | C8: 0 | D8: =(C8*1)/C7 -> 0 | E8: 0.08 | F8: =(F7*E8)/1 -> 2485.224 | G8: 0.01 | H8: =(H7*G8)/1 -> 19.08
B9: Compensación Dueño | C9: ='3 COMPENSACIÓN'!C20 -> 12000 | D9: =(C9*1)/C7 -> 0.40109727 | E9: 0.35 | F9: =(F7*E9)/1 -> 10872.855 | G9: 0.35 | H9: =(H7*G9)/1 -> 667.8
B10: Impuestos | C10: ='1 GASTOS'!C36 -> 4005.08 | D10: =(C10*1)/C7 -> 0.13386889 | E10: 0.17 | F10: =(F7*E10)/1 -> 5281.101 | G10: 0.13 | H10: =(H7*G10)/1 -> 248.04 | I10: ¿CUÁNTO TENGO QUE AHORRA EN GASTOS OPERACIÓN POR MES, EN EL PRÓXIMO TRIMESTRE?
B11: Gastos Operación | C11: ='1 GASTOS'!C25 -> 15383.43 | D11: =(C11*1)/C7 -> 0.51418765 | E11: 0.4 | F11: =(F7*E11)/1 -> 12426.12 | G11: =H11/H7 -> 0.51 | H11: =H7-H8-H9-H10 -> 973.08 | I11: =((H7*D11)-H11)/3 -> 2.6633429
C13: =SUM(C8:C11) -> 31388.51 | D13: =SUM(D8:D11) -> 1.0491538 | E13: =SUM(E8:E11) -> 1 | F13: =SUM(F8:F11) -> 31065.3 | G13: =SUM(G8:G11) -> 1 | H13: =SUM(H8:H11) -> 1908
B15: CASILLAS VERIFICACIÓN | C15: C7 | D15: 1 | E15: 1 | F15: F7 | G15: 1 | H15: G7
B18: NIVEL BÁSICO
F19: NIVEL AVANZADO
B20: INFORMACIÓN DE CADA CASILLA | F20: LA COLUMNA E LA PODEMOS TOCAR EN BASE A LA EXPERIENCIA
B22: B5 | C22: INGRESO TOTAL | D22: Viene de la pestaña 2 INGRESOS, C20 | F22: FILA 13 Y 15
B23: B6 | C23: PRODUCTOS QUE COMPRAS PARA VENDER + PERSONAL SUBCONTRATADO NECESARIO PARA PRESTAR UN SERVICIO AL CLIENTE) | D23: Viene de la pestaña 1 GASTOS, C23 | F23: SOLO DEBEMOS COMPOBAR QUE COINCIDAN (C13=C7, F13=F7, G13=G7)
B24: B7 | C24: INGRESO BRUTO | D24: Es la diferencia de las dos primeras.
B25: B8 | C25: GANANCIA - BENEFICIO | D25: Ganancia o beneficio de la empresa. No es tu sueldo. Esto es el dineo que queda en el banco a final de año despues de pagar TODOS los gastos, incluyendo impuestos. | F25: CASILLA GANACIAS
B26: B9 | C26: COMPENSACIÓN DEL DUEÑO | D26: Viene de la pestaña 3 COMPENSACIÓN, C20 | F26: La distrubución es un premio para las personas que han invertido dinero en el negocio
B27: B10 | C27: IMPUESTOS | D27: Viene de la pestaña 1 GASTOS, C26 | F27: No confundas ganancia con sueldo del dueño.
B28: B11 | C28: GASTOS DE OPERACIÓN | D28: Viene de la pestaña 1 GASTOS, C18 | F28: El sueldo es por trabajar, la ganancia es por invertir. Como las acciones
F29: Si hay préstamos 1% a socios y 99% a préstamos comenzando por el de menor importe
F30: Colchón de 3 meses sobre gastos.
C31: COLUMNA D
C32: Te va a decir como distibuyes actualmente el dinero que entra en la empresa en %. (No tocar) | F32: CASILLA GASTOS OPERSTIVOS DEL PRÓXIMO TRIMESTRE (META)
F33: LAS CELDAS H11 Y G11 SE CALCULAN AUTOMATICAMENTE. AL TENER QUE AUMENTAR LA GANANCIA Y LA COMPENSACIÓN DEL DUEÑO EN 1% , LOS GASTOS OPERATIVOS DEBEN BAJAR EN LA CANTIDAD QUE AUMENTARON ESAS DOS PARTIDAS, POR ESO, GASTOS OPERATIVOS SE CALCULAN CON UNA RESTA: GASTOS OPERATIVOS DEL PRÓXIMO TRIMESTRE (H11)=INGRESOS (H7) - GANANCIA (H8) -COMPESACIÓN (H9) - IMPUESTOS (H10)
B34: BÁSICO - LEEMOS NÚMEROS - COLUMNA E
B35: E8 | C35: GANANCIA - BENEFICIO | D35: Este es el porcentaje del ingreso bruto que deberías destinar a ganancia.
B36: E9 | C36: COMPENSACIÓN DEL DUEÑO | D36: Este es el porcentaje del ingreso bruto que deberías destinar a tu sueldo.
B37: E10 | C37: IMPUESTOS | D37: Este es el porcentaje del ingreso bruto que deberías destinar a Impuestos. Aunque la mejor forma de saberlo es ver años anteriores.
B38: E11 | C38: GASTOS DE OPERACIÓN | D38: Este es el porcentaje del ingreso bruto que deberías destinar a gastos operativos.
C41: COLUMNA F
C42: Te va a decir como deberías distibuir ese porcentaje en dinero. (No tocar)
C44: COLUMNA G - H
C45: Te va a decir como vas a dristribuir el dinero de la empresa durante el próximo trimestre + o -1

Sheet servicios
B2: METAS DE DISTRIBUCIÓN DE TUS PARTIDAS - NEGOCIOS DE SERVICIOS
C4: Lo que hice el año pasado en € | D4: Porcentaje de distribución al azar | E4: DISPOSICIÓN IDEAL | G4: % PRÓXIMO TRIMESTRE €
B5: Ingreso Total | C5: ='2 INGRESOS'!C26 -> 44379 | F5: =C5 -> 44379 | H5: =96000/4 -> 24000
B6: Productos/Sub. | C6: 0 | D6: =(C6*1)/C5 -> 0 | E6: 0 | F6: =(F5*E6)/1 -> 0 | G6: 0 | H6: =(H5*G6)/1 -> 0
B7: Ingreso Bruto | C7: =C5-C6 -> 44379 | F7: =F5-F6 -> 44379 | H7: =H5-H6 -> 24000
B8: Ganancia / Beneficio | C8: 0 | D8: =(C8*1)/C7 -> 0 | E8: 0.08 | F8: =(F7*E8)/1 -> 3550.32 | G8: 0.01 | H8: =(H7*G8)/1 -> 240
B9: Compensación Dueño | C9: ='3 COMPENSACIÓN'!C20 -> 12000 | D9: =(C9*1)/C7 -> 0.27039816 | E9: 0.35 | F9: =(F7*E9)/1 -> 15532.65 | G9: 0.185 | H9: =(H7*G9)/1 -> 4440
B10: Impuestos | C10: ='1 GASTOS'!C36 -> 4005.08 | D10: =(C10*1)/C7 -> 0.090247189 | E10: 0.17 | F10: =(F7*E10)/1 -> 7544.43 | G10: 0.17 | H10: =(H7*G10)/1 -> 4080 | I10: ¿CUÁNTO TENGO QUE AHORRA EN GASTOS OPERACIÓN POR MES, EN EL PRÓXIMO TRIMESTRE?
B11: Gastos Operación | C11: ='1 GASTOS'!C25+'1 GASTOS'!C33 -> 29844.5 | D11: =(C11*1)/C7 -> 0.67249149 | E11: 0.4 | F11: =(F7*E11)/1 -> 17751.6 | G11: =H11/H7 -> 0.635 | H11: =H7-H8-H9-H10 -> 15240 | I11: =((H7*D11)-H11)/3 -> 299.93195
C13: =SUM(C8:C11) -> 45849.58 | D13: =SUM(D8:D11) -> 1.0331368 | E13: =SUM(E8:E11) -> 1 | F13: =SUM(F8:F11) -> 44379 | G13: =SUM(G8:G11) -> 1 | H13: =SUM(H8:H11) -> 24000
B15: CASILLAS VERIFICACIÓN | C15: C7 | D15: 1 | E15: 1 | F15: F7 | G15: 1 | H15: G7
B18: NIVEL BÁSICO
F19: NIVEL AVANZADO
B20: INFORMACIÓN DE CADA CASILLA | F20: LA COLUMNA E LA PODEMOS TOCAR EN BASE A LA EXPERIENCIA
B22: B5 | C22: INGRESO TOTAL | D22: Viene de la pestaña 2 INGRESOS, C20 | F22: FILA 13 Y 15
B23: B6 | C23: PRODUCTOS QUE COMPRAS PARA VENDER + PERSONAL SUBCONTRATADO NECESARIO PARA PRESTAR UN SERVICIO AL CLIENTE) | D23: Viene de la pestaña 1 GASTOS, C23 | F23: SOLO DEBEMOS COMPOBAR QUE COINCIDAN (C13=C7, F13=F7, G13=G7)
B24: B7 | C24: INGRESO BRUTO | D24: Es la diferencia de las dos primeras.
B25: B8 | C25: GANANCIA - BENEFICIO | D25: Ganancia o beneficio de la empresa. No es tu sueldo. Esto es el dineo que queda en el banco a final de año despues de pagar TODOS los gastos, incluyendo impuestos. | F25: CASILLA GANACIAS
B26: B9 | C26: COMPENSACIÓN DEL DUEÑO | D26: Viene de la pestaña 3 COMPENSACIÓN, C20 | F26: La distrubución es un premio para las personas que han invertido dinero en el negocio
B27: B10 | C27: IMPUESTOS | D27: Viene de la pestaña 1 GASTOS, C26 | F27: No confundas ganancia con sueldo del dueño.
B28: B11 | C28: GASTOS DE OPERACIÓN | D28: Viene de la pestaña 1 GASTOS, C18 | F28: El sueldo es por trabajar, la ganancia es por invertir. Como las acciones
F29: Si hay préstamos 1% a socios y 99% a préstamos comenzando por el de menor importe
F30: Colchón de 3 meses sobre gastos.
C31: COLUMNA D
C32: Te va a decir como distibuyes actualmente (AL AZAR Y SIN PLANIFICACIÓN) el dinero que entra en la empresa en %. (No tocar) | F32: CASILLA GASTOS OPERSTIVOS DEL PRÓXIMO TRIMESTRE (META)
F33: LAS CELDAS H11 Y G11 SE CALCULAN AUTOMATICAMENTE. AL TENER QUE AUMENTAR LA GANANCIA Y LA COMPENSACIÓN DEL DUEÑO EN 1% , LOS GASTOS OPERATIVOS DEBEN BAJAR EN LA CANTIDAD QUE AUMENTARON ESAS DOS PARTIDAS, POR ESO, GASTOS OPERATIVOS SE CALCULAN CON UNA RESTA: GASTOS OPERATIVOS DEL PRÓXIMO TRIMESTRE (H11)=INGRESOS (H7) - GANANCIA (H8) -COMPESACIÓN (H9) - IMPUESTOS (H10)
B34: BÁSICO - LEEMOS NÚMEROS - COLUMNA E
B35: E8 | C35: GANANCIA - BENEFICIO | D35: Este es el porcentaje del ingreso bruto que deberías destinar a ganancia.
B36: E9 | C36: COMPENSACIÓN DEL DUEÑO | D36: Este es el porcentaje del ingreso bruto que deberías destinar a tu sueldo.
B37: E10 | C37: IMPUESTOS | D37: Este es el porcentaje del ingreso bruto que deberías destinar a Impuestos. Aunque la mejor forma de saberlo es ver años anteriores.
B38: E11 | C38: GASTOS DE OPERACIÓN | D38: Este es el porcentaje del ingreso bruto que deberías destinar a gastos operativos.
C41: COLUMNA F
C42: Te va a decir como deberías distibuir ese porcentaje en dinero. (No tocar)
C44: COLUMNA G - H
C45: Te va a decir como vas a dristribuir el dinero de la empresa durante el próximo trimestre + o -1

Sheet SEMANA 5

Sheet SEMANA 6
B24: ARCHIVO: ESTRATEGIAS Y PLAN DE REDUCCIÓN DE GASTOS | G24: PINCHA PARA VER EL ARCHIVO

Sheet 6 REDUCCIÓN DE GASTOS
A2: HOJA DE CLASIFICACIÓN Y REDCCIÓN DE GASTOS
A4: META DE REDUCCIÓN DE GASTOS | B4: 0.05
A6: GASTOS FIJOS / GASTOS OPERATIVOS | B6: CANTIDAD MENSUAL | C6: CANTIDAD ANUAL | D6: % DE IMPORTANCIA | E6: POSIBILIDAD DE ELIMINAR - SUSTITUIR - RENEGOCIAR | F6: META DE REDUCCIÓN | G6: NUEVO COSTO | H6: AHORRO MENSUAL | I6: AHORRO TRIMESTRAL | J6: AHORRO ANUAL
A7: Alquiler del local | B7: 0 | C7: =+B7*12 -> 0 | D7: =C7/$C$31 -> 0 | F7: =$B$4 -> 0.05 | G7: =B7*(1-F7) -> 0 | H7: =B7-G7 -> 0 | I7: =H7*3 -> 0 | J7: =H7*12 -> 0
A8: Salarios y sueldos del personal | B8: 0 | C8: =+B8*12 -> 0 | D8: =C8/$C$31 -> 0 | F8: =$B$4 -> 0.05 | G8: =B8*(1-F8) -> 0 | H8: =B8-G8 -> 0 | I8: =H8*3 -> 0 | J8: =H8*12 -> 0
A9: Servicios: Electricidad, agua, gas, y otros servicios públicos. | B9: 0 | C9: =+B9*12 -> 0 | D9: =C9/$C$31 -> 0 | F9: =$B$4 -> 0.05 | G9: =B9*(1-F9) -> 0 | H9: =B9-G9 -> 0 | I9: =H9*3 -> 0 | J9: =H9*12 -> 0
A10: Seguro del local | B10: 0 | C10: =+B10*12 -> 0 | D10: =C10/$C$31 -> 0 | F10: =$B$4 -> 0.05 | G10: =B10*(1-F10) -> 0 | H10: =B10-G10 -> 0 | I10: =H10*3 -> 0 | J10: =H10*12 -> 0
A11: Costos de licencias y permisos | B11: 51.425 | C11: =+B11*12 -> 617.1 | D11: =C11/$C$31 -> 0.060474921 | F11: =$B$4 -> 0.05 | G11: =B11*(1-F11) -> 48.85375 | H11: =B11-G11 -> 2.57125 | I11: =H11*3 -> 7.71375 | J11: =H11*12 -> 30.855
A12: Materiales de limpieza | B12: 5.9166667 | C12: =+B12*12 -> 71 | D12: =C12/$C$31 -> 0.0069578988 | F12: =$B$4 -> 0.05 | G12: =B12*(1-F12) -> 5.6208333 | H12: =B12-G12 -> 0.29583333 | I12: =H12*3 -> 0.8875 | J12: =H12*12 -> 3.55
A13: Publicidad y marketing | B13: 89.916667 | C13: =+B13*12 -> 1079 | D13: =C13/$C$31 -> 0.10574046 | E13: ELIMINAR | F13: =$B$4 -> 0.05 | G13: =B13*(1-F13) -> 85.420833 | H13: =B13-G13 -> 4.4958333 | I13: =H13*3 -> 13.4875 | J13: =H13*12 -> 53.95
A14: Productos de oficina | B14: 10.416667 | C14: =+B14*12 -> 125 | D14: =C14/$C$31 -> 0.012249822 | F14: =$B$4 -> 0.05 | G14: =B14*(1-F14) -> 9.8958333 | H14: =B14-G14 -> 0.52083333 | I14: =H14*3 -> 1.5625 | J14: =H14*12 -> 6.25
A15: Mantenimiento y reparaciones | B15: 0 | C15: =+B15*12 -> 0 | D15: =C15/$C$31 -> 0 | F15: =$B$4 -> 0.05 | G15: =B15*(1-F15) -> 0 | H15: =B15-G15 -> 0 | I15: =H15*3 -> 0 | J15: =H15*12 -> 0
A16: Servicios de gestoría | B16: 66.55 | C16: =+B16*12 -> 798.6 | D16: =C16/$C$31 -> 0.078261662 | F16: =$B$4 -> 0.05 | G16: =B16*(1-F16) -> 63.2225 | H16: =B16-G16 -> 3.3275 | I16: =H16*3 -> 9.9825 | J16: =H16*12 -> 39.93
A17: Cuota de autónomos | B17: 110.71 | C17: =+B17*12 -> 1328.52 | D17: =C17/$C$31 -> 0.13019307 | E17: NINGUNA | F17: 0 | G17: =B17*(1-F17) -> 110.71 | H17: =B17-G17 -> 0 | I17: =H17*3 -> 0 | J17: =H17*12 -> 0
A18: Formación | B18: 51.583333 | C18: =+B18*12 -> 619 | D18: =C18/$C$31 -> 0.060661118 | F18: =$B$4 -> 0.05 | G18: =B18*(1-F18) -> 49.004167 | H18: =B18-G18 -> 2.5791667 | I18: =H18*3 -> 7.7375 | J18: =H18*12 -> 30.95
A19: Gastos bancarios | B19: 12.326667 | C19: =+B19*12 -> 147.92 | D19: =C19/$C$31 -> 0.014495949 | F19: =$B$4 -> 0.05 | G19: =B19*(1-F19) -> 11.710333 | H19: =B19-G19 -> 0.61633333 | I19: =H19*3 -> 1.849 | J19: =H19*12 -> 7.396
A20: Web y comunicación | B20: 432.8325 | C20: =+B20*12 -> 5193.99 | D20: =C20/$C$31 -> 0.50900362 | E20: ELIMINAR | F20: 0.5 | G20: =B20*(1-F20) -> 216.41625 | H20: =B20-G20 -> 216.41625 | I20: =H20*3 -> 649.24875 | J20: =H20*12 -> 2596.995
A21: Telefonia | B21: 6.925 | C21: =+B21*12 -> 83.1 | D21: =C21/$C$31 -> 0.0081436816 | F21: =$B$4 -> 0.05 | G21: =B21*(1-F21) -> 6.57875 | H21: =B21-G21 -> 0.34625 | I21: =H21*3 -> 1.03875 | J21: =H21*12 -> 4.155
A22: Varios (protecc datos) | B22: 11.75 | C22: =+B22*12 -> 141 | D22: =C22/$C$31 -> 0.013817799 | F22: =$B$4 -> 0.05 | G22: =B22*(1-F22) -> 11.1625 | H22: =B22-G22 -> 0.5875 | I22: =H22*3 -> 1.7625 | J22: =H22*12 -> 7.05
A23: Flores | B23: 584.52417 | C23: =+B23*12 -> 7014.29 | D23: =C23/$C$31 -> 0.68739043 | E23: NINGUNA | F23: =$B$4 -> 0.05 | G23: =B23*(1-F23) -> 555.29796 | H23: =B23-G23 -> 29.226208 | I23: =H23*3 -> 87.678625 | J23: =H23*12 -> 350.7145
A24: Materiales (cristales etc) | B24: 127.10667 | C24: =+B24*12 -> 1525.28 | D24: =C24/$C$31 -> 0.14947527 | E24: NINGUNA | F24: =$B$4 -> 0.05 | G24: =B24*(1-F24) -> 120.75133 | H24: =B24-G24 -> 6.3553333 | I24: =H24*3 -> 19.066 | J24: =H24*12 -> 76.264
A25: Packaging | B25: 65.600833 | C25: =+B25*12 -> 787.21 | D25: =C25/$C$31 -> 0.077145458 | F25: =$B$4 -> 0.05 | G25: =B25*(1-F25) -> 62.320792 | H25: =B25-G25 -> 3.2800417 | I25: =H25*3 -> 9.840125 | J25: =H25*12 -> 39.3605
A26: Mensajería | B26: 118.1275 | C26: =+B26*12 -> 1417.53 | D26: =C26/$C$31 -> 0.13891592 | E26: SUSTITUIR | F26: =$B$4 -> 0.05 | G26: =B26*(1-F26) -> 112.22112 | H26: =B26-G26 -> 5.906375 | I26: =H26*3 -> 17.719125 | J26: =H26*12 -> 70.8765
A27: Contrataciones temporales- impuestos | B27: 321.75417 | C27: =+B27*12 -> 3861.05 | D27: =C27/$C$31 -> 0.3783774 | E27: NINGUNA | F27: =$B$4 -> 0.05 | G27: =B27*(1-F27) -> 305.66646 | H27: =B27-G27 -> 16.087708 | I27: =H27*3 -> 48.263125 | J27: =H27*12 -> 193.0525
A28: Impuestos sobre la renta IRPF (Se paga una vez al año en Junio del año siguiente) | B28: -10.228182 | C28: =+B28*12 -> -122.73818 | D28: =C28/$C$31 -> -0.012028167 | F28: =$B$4 -> 0.05 | G28: =B28*(1-F28) -> -9.7167727 | H28: =B28-G28 -> -0.51140909 | I28: =H28*3 -> -1.5342273 | J28: =H28*12 -> -6.1369091
A29: Pagos trimestrales | B29: 70.179091 | C29: =+B29*12 -> 842.14909 | D29: =C29/$C$31 -> 0.082529411 | F29: =$B$4 -> 0.05 | G29: =B29*(1-F29) -> 66.670136 | H29: =B29-G29 -> 3.5089545 | I29: =H29*3 -> 10.526864 | J29: =H29*12 -> 42.107455
A30: Otros | C30: =+B30*12 -> 0 | D30: =C30/$C$31 -> 0 | F30: =$B$4 -> 0.05 | G30: =B30*(1-F30) -> 0 | H30: =B30-G30 -> 0 | I30: =H30*3 -> 0 | J30: =H30*12 -> 0
A31: TOTAL | B31: =SUM(B7:B22) -> 850.3525 | C31: =SUM(C7:C22) -> 10204.23 | D31: =C31/$C$31 -> 1 | G31: =SUM(G7:G22) -> 618.59575 | H31: =SUM(H7:H22) -> 231.75675 | I31: =SUM(I7:I22) -> 695.27025 | J31: =SUM(J7:J22) -> 2781.081

Sheet SEMANA 7

Sheet 7 CUÁNTO VENDER AL DÍA
B2: ¿CUÁNTO VENDER AL DÍA?
B4: Cuanto días estás abierta el año | C4: Cuantas horas abres "de venta"
B5: 250 | C5: 8
B7: Si hay días que trabajas medio tiempo, entonces utiliza los siguientes cuadros:
B9: Cuanto días estás abierta el año a tiempo completo | C9: Cuantas horas abres "de venta"
B10: 200 | C10: 8
B12: Cuanto días estás abierta el año a tiempo parcial | C12: Cuantas horas abres "de venta"
B13: 50 | C13: 5
B16: GASTOS ANUALES
B17: ='1 GASTOS'!C25 -> 15383.43 | D17: ¡Esta es la suma de todos tus gastos anuales!
B19: GASTOS MENSUALES 12 meses
B20: =B17/12 -> 1281.9525 | D20: ¡Este es el promedio mensual de tus gastos!
B22: GASTOS DIARIOS
B23: =B17/365 -> 42.146384 | D23: ¡Este es el promedio diario de tus gastos!
B25: SI TODOS LOS DÍAS TRABAJAS LAS MISMAS HORAS
B26: MÍNIMA FACTURACIÓN DIARIA
B27: =B17/B5 -> 61.53372 | D27: ¡Esta es la facturación promedio que deberías tener cada día!
B29: MÍNIMA FACTURACIÓN POR HORA
B30: =B27/C5 -> 7.691715 | D30: ¡Esta es la facturación promedio que deberías tener cada hora!
B32: SI TIENES DÍAS DE MEDIA JORNADA
B33: MÍNIMA FACTURACIÓN DIARIA LOS DÍAS DE 8 HORAS
B34: =B40*C10 -> 66.522941 | D34: ¡Esta es la facturación promedio que deberías tener cada día completo!
B36: MÍNIMA FACTURACIÓN DIARIA LOS DÍAS DE 5 HORAS
B37: =B40*C13 -> 41.576838 | D37: ¡Esta es la facturación promedio que deberías tener cada día parcial!
B39: MÍNIMA FACTURACIÓN POR HORA
B40: =B17/((B10*C10)+(B13*C13)) -> 8.3153676 | D40: ¡Esta es la facturación promedio que deberías tener cada hora!

Sheet 8 TICKET MEDIO
B1: TICKET MEDIO DE LOS ÚLTIMOS 6 MESES
B4: MES | C4: FACTURACIÓN | D4: NÚMERO DE CLIENTES | E4: TICKET MEDIO
B5: 1 | E5: =C5/D5 -> #DIV/0!
B6: 2 | E6: =C6/D6 -> #DIV/0!
B7: 3 | E7: =C7/D7 -> #DIV/0!
B8: 4 | E8: =C8/D8 -> #DIV/0!
B9: 5 | E9: =C9/D9 -> #DIV/0!
B10: 6 | E10: =C10/D10 -> #DIV/0!
B11: TOTAL | E11: =C11/D11 -> #DIV/0!
B14: COMPARACIÓN DEL TICKET MEDIO CON LA MÍNIMA FACTURACIÓN POR HORA
B16: SI TODOS LOS DÍAS TRABAJAS LAS MISMA HORAS
B17: Ticket Medio | D17: =E11 -> #DIV/0!
B18: Mínina Facturación por hora | D18: ='7 CUÁNTO VENDER AL DÍA'!B30 -> 7.691715
B19: Factor de relación | D19: =D17/D18 -> #DIV/0!
B21: SI TIENES DÍAS DE MEDIA JORNADA
B22: Ticket Medio | D22: =E11 -> #DIV/0!
B23: Mínina Facturación por hora | D23: ='7 CUÁNTO VENDER AL DÍA'!B40 -> 8.3153676
B24: Factor de relación | D24: =D22/D23 -> #DIV/0!

Sheet ESTRATEGIAS EXTRAS
